<?xml version="1.0" encoding="utf-8"?>
<!-- This URDF was automatically created by SolidWorks to URDF Exporter! Originally created by Stephen Brawner (brawner@gmail.com) 
     Commit Version: 1.6.0-4-g7f85cfe  Build Version: 1.6.7995.38578
     For more information, please see http://wiki.ros.org/sw_urdf_exporter -->
<robot
  name="EGU50_version_2">
  <link name="world_link" />
  <link
    name="base_link">
    <inertial>
      <origin
        xyz="4.36039249165719E-07 0.000379884074531637 0.0387490097277167"
        rpy="0 0 0" />
      <mass
        value="0.663474916897533" />
      <inertia
        ixx="0.00114971001815264"
        ixy="-1.84232957850261E-07"
        ixz="-9.465031052129E-09"
        iyy="0.000618426886337379"
        iyz="9.73355102540173E-07"
        izz="0.00110317775862493" />
    </inertial>
    <visual>
      <origin
        xyz="0 0 0"
        rpy="0 0 0" />
      <geometry>
        <mesh
          filename="file:///home/ros/test_for_urdf/src/eug50_version_2/meshes/base_link.stl" />
      </geometry>
      <material
        name="">
        <color
          rgba="0.792156862745098 0.819607843137255 0.933333333333333 1" />
      </material>
    </visual>
    <collision>
      <origin
        xyz="0 0 0"
        rpy="0 0 0" />
      <geometry>
        <mesh
          filename="file:///home/ros/test_for_urdf/src/eug50_version_2/meshes/base_link.stl" />
      </geometry>
    </collision>
  </link>
  <joint name="world_to_base" type="fixed">
    <parent link="world_link" />
    <child link="base_link" />
  </joint>
  <link
    name="translational_1">
    <inertial>
      <origin
        xyz="1.4263E-11 -0.0072452 -1.7621E-09"
        rpy="0 0 0" />
      <mass
        value="0.01085" />
      <inertia
        ixx="4.5433E-06"
        ixy="-3.9379E-16"
        ixz="1.0067E-14"
        iyy="4.5738E-06"
        iyz="9.2402E-14"
        izz="3.0604E-07" />
    </inertial>
    <visual>
      <origin
        xyz="0 0 0"
        rpy="0 0 0" />
      <geometry>
        <mesh
          filename="file:///home/ros/test_for_urdf/src/eug50_version_2/meshes/translational_1.stl" />
      </geometry>
      <material
        name="">
        <color
          rgba="0.69412 0.75294 0.77255 1" />
      </material>
    </visual>
    <collision>
      <origin
        xyz="0 0 0"
        rpy="0 0 0" />
      <geometry>
        <mesh
          filename="file:///home/ros/test_for_urdf/src/eug50_version_2/meshes/translational_1.stl" />
      </geometry>
    </collision>
  </link>
  <joint
    name="translational_joint_1"
    type="continuous">
    <origin
      xyz="-0.01258 0.021 0.083"
      rpy="1.5708 0 3.1416" />
    <parent
      link="base_link" />
    <child
      link="translational_1" />
    <axis
      xyz="0 0 1" />
  </joint>

  <link
    name="translational_2">
    <inertial>
      <origin
        xyz="1.4263E-11 -0.0072452 -1.7621E-09"
        rpy="0 0 0" />
      <mass
        value="0.01085" />
      <inertia
        ixx="4.5433E-06"
        ixy="-3.9379E-16"
        ixz="1.0067E-14"
        iyy="4.5738E-06"
        iyz="9.2402E-14"
        izz="3.0604E-07" />
    </inertial>
    <visual>
      <origin
        xyz="0 0 0"
        rpy="0 0 0" />
      <geometry>
        <mesh
          filename="file:///home/ros/test_for_urdf/src/eug50_version_2/meshes/translational_2.stl" />
      </geometry>
      <material
        name="">
        <color
          rgba="0.69412 0.75294 0.77255 1" />
      </material>
    </visual>
    <collision>
      <origin
        xyz="0 0 0"
        rpy="0 0 0" />
      <geometry>
        <mesh
          filename="file:///home/ros/test_for_urdf/src/eug50_version_2/meshes/translational_2.stl" />
      </geometry>
    </collision>
  </link>
  <joint
    name="translational_joint_2"
    type="continuous">
    <origin
      xyz="0.01258 -0.021 0.083"
      rpy="1.5708 0 0" />
    <parent
      link="base_link" />
    <child
      link="translational_2" />
    <axis
      xyz="0 0 1" />
  </joint>

  <link
    name="trl_1">
    <inertial>
      <origin
        xyz="-7.7141E-05 -1.6517E-07 -0.00014475"
        rpy="0 0 0" />
      <mass
        value="0.00012871" />
      <inertia
        ixx="1.2696E-09"
        ixy="-1.5694E-12"
        ixz="-1.2932E-12"
        iyy="1.8096E-08"
        iyz="-2.7689E-15"
        izz="1.9364E-08" />
    </inertial>
    <visual>
      <origin
        xyz="0 0 0"
        rpy="0 0 0" />
      <geometry>
        <mesh
          filename="file:///home/ros/test_for_urdf/src/eug50_version_2/meshes/trl_1.stl" />
      </geometry>
      <material
        name="">
        <color
          rgba="0.79216 0.81961 0.93333 1" />
      </material>
    </visual>
    <collision>
      <origin
        xyz="0 0 0"
        rpy="0 0 0" />
      <geometry>
        <mesh
          filename="file:///home/ros/test_for_urdf/src/eug50_version_2/meshes/trl_1.stl" />
      </geometry>
    </collision>
  </link>
  <joint
    name="fixed_1"
    type="fixed">
    <origin
      xyz="0.0353 0 0.0701"
      rpy="1.5708 0 -1.5708" />
    <parent
      link="base_link" />
    <child
      link="trl_1" />
    <axis
      xyz="0 0 0" />
  </joint>
  <link
    name="trl_2">
    <inertial>
      <origin
        xyz="-7.7141E-05 1.6517E-07 0.00014475"
        rpy="0 0 0" />
      <mass
        value="0.00012871" />
      <inertia
        ixx="1.2696E-09"
        ixy="1.5694E-12"
        ixz="1.2932E-12"
        iyy="1.8096E-08"
        iyz="-2.7689E-15"
        izz="1.9364E-08" />
    </inertial>
    <visual>
      <origin
        xyz="0 0 0"
        rpy="0 0 0" />
      <geometry>
        <mesh
          filename="file:///home/ros/test_for_urdf/src/eug50_version_2/meshes/trl_2.stl" />
      </geometry>
      <material
        name="">
        <color
          rgba="0.79216 0.81961 0.93333 1" />
      </material>
    </visual>
    <collision>
      <origin
        xyz="0 0 0"
        rpy="0 0 0" />
      <geometry>
        <mesh
          filename="file:///home/ros/test_for_urdf/src/eug50_version_2/meshes/trl_2.stl" />
      </geometry>
    </collision>
  </link>
  <joint
    name="fixed_2"
    type="fixed">
    <origin
      xyz="-0.0353 0 0.0701"
      rpy="-1.5708 0 1.5708" />
    <parent
      link="base_link" />
    <child
      link="trl_2" />
    <axis
      xyz="0 0 0" />
  </joint>
</robot>
